<?xml version="1.0"?>
<robot xmlns:xacro="http://www.ros.org/wiki/xacro">

  <xacro:property name="wheel_radius" value="0.1" />
  <xacro:property name="wheel_separation" value="0.4" />
  <xacro:property name="wheel_width" value="0.05" />
  <xacro:property name="wheel_mass" value="4.3" />

  <xacro:macro name="diff_wheel" params="prefix side y_reflect">
    <link name="${prefix}${side}_wheel_link">
      <visual>
        <origin xyz="0 ${-wheel_separation/2} ${-wheel_radius}" rpy="${pi/2} 0 0"/>
        <geometry>
          <mesh filename="file://$(find open_amr_description)/meshes/open_amr/visual/big_wheel.stl" scale="0.1 0.1 0.1"/>
          <material name="rubber_black">
            <color rgba="0.05 0.05 0.05 1.0"/>
          </material>
        </geometry>

      </visual>
 
      <collision>
        <origin xyz="0 0 0" rpy="${pi/2} 0 0"/>
        <geometry>
          <cylinder radius="${wheel_radius}" length="${wheel_width}"/>
        </geometry>
      </collision>

      <inertial>
        <origin xyz="0 0 0" rpy="0 0 0"/>
        <mass value="${wheel_mass}"/>
        <inertia
          ixx="${(wheel_mass/12.0) * (3*wheel_radius*wheel_radius + wheel_width*wheel_width)}" ixy="0" ixz="0"
          iyy="${(wheel_mass/2.0) * (wheel_radius*wheel_radius)}" iyz="0"
          izz="${(wheel_mass/12.0) * (3*wheel_radius*wheel_radius + wheel_width*wheel_width)}"/>
      </inertial>
    </link>

    <joint name="${prefix}${side}_wheel_joint" type="continuous">
      <axis xyz="0 1 0"/>
      <parent link="${prefix}base_link"/>
      <child link="${prefix}${side}_wheel_link"/>
      <origin xyz="0 ${y_reflect*(wheel_separation/2)} 0" rpy="0 0 0"/>
    </joint>

    <gazebo reference="${prefix}${side}_wheel_link">
      <surface>
        <friction>
          <ode>
              <mu>1.0</mu>
              <mu2>0.0</mu2>
          </ode>
        </friction>
      </surface>
      <visual>
          <material>
              <ambient>0.05 0.05 0.05 1.0</ambient>
              <diffuse>0.05 0.05 0.05 1.0</diffuse>
              <specular>0.05 0.05 0.05 1.0</specular>
              <emissive>0.0 0.0 0.0 0.0</emissive>
          </material>
      </visual>
    </gazebo>
  </xacro:macro>
</robot>